Workbook

Sheet total
A1: 45413 | D1: 45445 | G1: 45474 | J1: 45505 | M1: 45566 | P1: 45597 | S1: 45627 | V1: 45658 | Y1: 45689 | AB1: 45717 | AE1: 45748 | AH1: 45779 | AK1: 45809 | AN1: 45839 | AQ1: 45870 | AT1: 45931 | AW1: 45962 | AZ1: 45992 | BC1: 46034 | BF1: 46080 | BI1: ???
A2: Bond | B2: 951450 | D2: Bond | E2: 951450 | G2: pf | H2: 808008 | J2: pf | K2: 808008 | M2: pf | N2: 796070 | P2: pf | Q2: 796070 | S2: pf | T2: 833372 | V2: pf | W2: 833372 | Y2: pf | Z2: 833372 | AB2: pf | AC2: 833372 | AE2: pf | AF2: 865324 | AH2: pf | AI2: 865324 | AK2: pf | AL2: 865324 | AN2: pf | AO2: 865324 | AQ2: pf | AR2: 865324 | AT2: pf | AU2: 865324 | AW2: pf | AX2: 865324 | AZ2: pf | BA2: 865324 | BC2: pf | BD2: =651717+358128 -> 1009845 | BF2: pf | BG2: =651717+358128 -> 1009845 | BI2: aniketstocks | BJ2: =441521 -> 441521
A3: pf | B3: 668528 | D3: pf | E3: 668528 | G3: tata mmf | H3: 1000345.7 | J3: tata mmf | K3: 1007126.1 | M3: tata mmf | N3: 1019698.2 | P3: tata mmf | Q3: 1026151 | S3: tata mmf | T3: 1032099.8 | V3: tata mmf | W3: 1038473.1 | Y3: tata mmf | Z3: 1045060.9 | AB3: tata mmf | AC3: 1050943.1 | AE3: tata mmf | AF3: 1060365.4 | AH3: tata mmf | AI3: 1069730.5 | AK3: tata mmf | AL3: 1076904 | AN3: tata mmf | AO3: 1084164.5 | AQ3: tata mmf | AR3: 1090508.8 | AT3: tata mmf | AU3: 1101242.3 | AW3: tata mmf | AX3: 1106977.3 | AZ3: tata mmf | BA3: 1112472.9 | BC3: tata mmf | BD3: 1118888.2 | BF3: tata mmf | BG3: 1128386 | BI3: amrutastocks | BJ3: =1415595.78 -> 1415595.8
A4: axis overnight | B4: 1419634.1 | D4: axis overnight | E4: 1427820.6 | G4: axis overnight | H4: 1435262.6 | J4: axis overnight | K4: 1443090.3 | M4: axis overnight | N4: 0 | P4: axis overnight | Q4: 0 | S4: axis overnight | T4: 0 | V4: axis overnight | W4: 0 | Y4: axis overnight | Z4: 0 | AB4: axis overnight | AC4: 0 | AE4: amruta tata mmf | AF4: 0 | AH4: amruta tata mmf | AI4: 1006035.5 | AK4: amruta tata mmf | AL4: 1012782 | AN4: - | AO4: 0 | AQ4: - | AR4: 0 | AT4: - | AU4: 0 | AW4: - | AX4: 0 | AZ4: - | BA4: 0 | BC4: - | BD4: 0 | BF4: - | BG4: 0 | BI4: MO midcap | BJ4: 869738
A5: nippon overnight | B5: 905550.14 | D5: nippon overnight | E5: 910768.4 | G5: nippon overnight | H5: 915518 | J5: nippon overnight | K5: 920507.89 | M5: nippon overnight | N5: 0 | P5: nippon overnight | Q5: 0 | S5: nippon overnight | T5: 0 | V5: nippon overnight | W5: 0 | Y5: nippon overnight | Z5: 0 | AB5: nippon overnight | AC5: 0 | AE5: amruta absl corp | AF5: 0 | AH5: amruta absl corp | AI5: 504576.06 | AK5: amruta absl corp | AL5: 509925 | AN5: amruta all debt funds | AO5: =2528607.77+760000 -> 3288607.8 | AQ5: amruta all debt funds | AR5: =512239.74+1006366.14+764716.63+1025576.59 -> 3308899.1 | AT5: amruta all debt funds | AU5: =3327559.24 -> 3327559.2 | AW5: amruta all debt funds | AX5: =3350253 -> 3350253 | AZ5: amruta all debt funds | BA5: 3366751 | BC5: amruta all debt funds | BD5: 3375222 | BF5: amruta all debt funds | BG5: 0 | BI5: hdfc midcap | BJ5: 898979
A6: uti liquid | B6: 3489132.5 | D6: uti liquid | E6: 3510938.9 | G6: uti liquid | H6: 3530497.6 | J6: uti liquid | K6: 3552097.4 | M6: uti liquid | N6: 3593855.3 | P6: uti liquid | Q6: 3616708 | S6: uti liquid | T6: 3635204.7 | V6: uti liquid | W6: 3657159.7 | Y6: uti liquid | Z6: 3678943.7 | AB6: uti liquid | AC6: 3699012.8 | AE6: uti liquid | AF6: 3725155.6 | AH6: uti liquid | AI6: 3747212.5 | AK6: uti liquid | AL6: 3766172 | AN6: uti liquid | AO6: 3786903.5 | AQ6: uti liquid | AR6: 3805488.2 | AT6: uti liquid | AU6: 3842143.8 | AW6: uti liquid | AX6: 3860813.8 | AZ6: uti liquid | BA6: 3879432.8 | BC6: uti liquid | BD6: 3902964.6 | BF6: uti liquid | BG6: 3935452 | BI6: hdfc index | BJ6: 3914849
A7: sbi liquid | B7: 5119373.7 | D7: sbi liquid | E7: 5151139.7 | G7: sbi liquid | H7: 5179527 | J7: sbi liquid | K7: 5211161.5 | M7: sbi liquid | N7: 5271991.9 | P7: sbi liquid | Q7: 4304060 | S7: sbi liquid | T7: 4325818.9 | V7: sbi liquid | W7: 4351589.1 | Y7: sbi liquid | Z7: 4377218.1 | AB7: sbi liquid | AC7: 4401073.6 | AE7: sbi liquid | AF7: 4431262.7 | AH7: sbi liquid | AI7: 4457128.4 | AK7: sbi liquid | AL7: 4480023 | AN7: sbi liquid | AO7: 4504517.1 | AQ7: sbi liquid | AR7: 4526261.5 | AT7: sbi liquid | AU7: 4568910.5 | AW7: sbi liquid | AX7: 4590800 | AZ7: sbi liquid | BA7: 4612900.3 | BC7: sbi liquid | BD7: 4640403.4 | BF7: sbi liquid | BG7: 4678503 | BI7: icici index | BJ7: 3887785
A8: sbi savings | B8: 2503512.2 | D8: sbi savings | E8: 2519163.8 | G8: sbi savings | H8: 2534384.8 | J8: sbi savings | K8: 2551082.3 | M8: sbi savings | N8: 2582502.4 | P8: sbi savings | Q8: 2598548 | S8: sbi savings | T8: 2613122.7 | V8: sbi savings | W8: 2629100.4 | Y8: sbi savings | Z8: 2644432 | AB8: sbi savings | AC8: 2659653 | AE8: sbi savings | AF8: 2682650.5 | AH8: sbi savings | AI8: 2706097.1 | AK8: sbi savings | AL8: 2724664 | AN8: sbi savings | AO8: 2742217.6 | AQ8: sbi savings | AR8: 2758029.2 | AT8: sbi savings | AU8: 2784385.9 | AW8: sbi savings | AX8: 2798567.1 | AZ8: sbi savings | BA8: 2813179 | BC8: sbi savings | BD8: 2829027.4 | BF8: sbi savings | BG8: 2851292 | BI8: Zerodha Cash (Aniket+Amruta) | BJ8: 152000
A9: Total funds | B9: =SUM(B2:B8) -> 15057181 | D9: Total funds | E9: =SUM(E2:E8) -> 15139809 | G9: Total funds | H9: =SUM(H2:H8) -> 15403544 | J9: Total funds | K9: =SUM(K2:K8) -> 15493073 | M9: Total funds | N9: =SUM(N2:N8) -> 13264118 | P9: Total funds | Q9: =SUM(Q2:Q8) -> 12341537 | S9: Total funds | T9: =SUM(T2:T8) -> 12439618 | V9: Total funds | W9: =SUM(W2:W8) -> 12509694 | Y9: Total funds | Z9: =SUM(Z2:Z8) -> 12579027 | AB9: Total funds | AC9: =SUM(AC2:AC8) -> 12644054 | AE9: Total funds | AF9: =SUM(AF2:AF8) -> 12764758 | AH9: Total funds | AI9: =SUM(AI2:AI8) -> 14356104 | AK9: Total funds | AL9: =SUM(AL2:AL8) -> 14435794 | AM9: =AL9-AI9 -> 79689.85 | AN9: Total funds | AO9: =SUM(AO2:AO8) -> 16271734 | AP9: =AO9-AL9 -> 1835940.5 | AQ9: Total funds | AR9: =SUM(AR2:AR8) -> 16354511 | AS9: =AR9-AO9 -> 82776.28 | AT9: Total funds | AU9: =SUM(AU2:AU8) -> 16489566 | AV9: =AU9-AR9 -> 135055.07 | AW9: Total funds | AX9: =SUM(AX2:AX8) -> 16572735 | AY9: =AX9-AU9 -> 83169.36 | AZ9: Total funds | BA9: =SUM(BA2:BA8) -> 16650060 | BB9: =BA9-AX9 -> 77324.85 | BC9: Total funds | BD9: =SUM(BD2:BD8) -> 16876351 | BE9: =BD9-BA9 -> 226290.65 | BF9: Total funds | BG9: =SUM(BG2:BG8) -> 13603478 | BI9: Sbi | BJ9: 221432
BI10: Hdfc | BJ10: =193313 -> 193313
A11: Equity | B11: =B12+B13+B14 -> 7897295.6 | D11: Equity | E11: =E12+E13+E14 -> 7902790.5 | G11: Equity | H11: =H12+H13+H14 -> 8434569.9 | J11: Equity | K11: =K12+K13+K14 -> 8765467.6 | M11: Equity | N11: =N12+N13+N14 -> 9540736.5 | P11: Equity | Q11: =Q12+Q13+Q14 -> 9551827.4 | S11: Equity | T11: =T12+T13+T14 -> 9729093.5 | V11: Equity Total | W11: =W12+W13+W14 -> 9512605 | Y11: Equity Total | Z11: =Z12+Z13+Z14 -> 9455702.2 | AB11: Equity Total | AC11: =AC12+AC13+AC14 -> 8902654.4 | AE11: Equity Total | AF11: =AF12+AF13+AF14 -> 10361984 | AH11: Equity Total | AI11: =AI12+AI13+AI14 -> 10758562 | AK11: Equity Total | AL11: =AL12+AL13+AL14 -> 11024068 | AN11: Equity Total | AO11: =AO12+AO13+AO14 -> 11374078 | AQ11: Equity Total | AR11: =AR12+AR13+AR14 -> 11058343 | AT11: Equity Total | AU11: =AU12+AU15+AU16+AU13+AU14 -> 11349935 | AW11: Equity Total | AX11: =AX12+AX15+AX16+AX13+AX14 -> 11800330 | AZ11: Equity Total | BA11: =BA12+BA15+BA16+BA13+BA14 -> 11915366 | BC11: Equity Total | BD11: =BD12+BD15+BD16+BD13+BD14 -> 11854533 | BF11: Equity Total | BG11: =BG12+BG15+BG16+BG13+BG14 -> 11428468 | BI11: Amruta HDFC | BJ11: 103000
A12: niftybees | B12: 1133271.9 | D12: niftybees | E12: 1138211.8 | G12: niftybees | H12: 1215890.3 | J12: niftybees | K12: 1261391.6 | M12: niftybees+bajaj | N12: =1306484.96+32731.3+425646 -> 1764862.3 | P12: niftybees+bajaj | Q12: 1647170.3 | S12: niftybees+bajajhfl | T12: 1846333.6 | V12: niftybees+bajajhfl | W12: =1204333.68+585861.5 -> 1790195.2 | Y12: niftybees+stocks | Z12: =1188335.72+530416.76+51072 -> 1769824.5 | AB12: niftybees+stocks | AC12: =1126609.88+498727.5+37060 -> 1662397.4 | AE12: niftybees+stocks | AF12: =1183939+560409+38772+1000000 -> 2783120 | AH12: niftybees+bajajhfl+anantraj+amrutastocks | AI12: =1828679.9+969341 -> 2798020.9 | AK12: niftybees+bajajhfl+anantraj+amrutastocks+amrutazerodhacash | AL12: =1864148+1019266+7834 -> 2891248 | AN12: niftybees+bajajhfl+anantraj+amrutastocks+amrutazerodhacash | AO12: =1902627.96+1082498.45+5777 -> 2990903.4 | AQ12: niftybees+bajajhfl+anantraj+amrutastocks+amrutazerodhacash | AR12: =1013107.65+1820130.84+75000 -> 2908238.5 | AT12: aniketstocks+amrutastocks+amrutazerodhacash | AU12: =567109.42+1473252.4 -> 2040361.8 | AW12: aniketstocks+amrutastocks+amrutazerodhacash | AX12: =557158.5+1497436.09 -> 2054594.6 | AZ12: aniketstocks+amrutastocks+amrutazerodhacash | BA12: =525053+1482138 -> 2007191 | BC12: aniketstocks+amrutastocks+amrutazerodhacash | BD12: =487057.4+1507227.3 -> 1994284.7 | BF12: aniketstocks+amrutastocks+amrutazerodhacash | BG12: =441521+1415595.78 -> 1857116.8 | BI12: crypto | BJ12: 0
A13: hdfc index | B13: 3380314.3 | D13: hdfc index | E13: 3380481.9 | G13: hdfc index | H13: 3607298.6 | J13: hdfc index | K13: 3749945.8 | M13: hdfc index | N13: 3885675.2 | P13: hdfc index | Q13: 4252946.1 | S13: hdfc index | T13: 4241222.8 | V13: hdfc index | W13: 4154869.6 | Y13: hdfc index | Z13: 4135250 | AB13: hdfc index | AC13: 3895492.1 | AE13: hdfc index | AF13: 4077846.8 | AH13: hdfc index | AI13: 4283437.8 | AK13: hdfc index | AL13: 4376134 | AN13: hdfc index | AO13: 4510752.7 | AQ13: hdfc index | AR13: 4385311.7 | AT13: MO midcap | AU13: 951058.7 | AW13: MO midcap | AX13: 1002795.5 | AZ13: MO midcap | BA13: 997849.75 | BC13: MO midcap | BD13: 956939.7 | BF13: MO midcap | BG13: 869738
A14: icici index | B14: 3383709.5 | D14: icici index | E14: 3384096.8 | G14: icici index | H14: 3611381 | J14: icici index | K14: 3754130.3 | M14: icici index | N14: 3890199 | P14: icici index | Q14: 3651710.9 | S14: icici index | T14: 3641537.1 | V14: icici index | W14: 3567540.2 | Y14: icici index | Z14: 3550627.7 | AB14: icici index | AC14: 3344764.9 | AE14: icici index | AF14: 3501017.5 | AH14: icici index | AI14: 3677102.9 | AK14: icici index | AL14: 3756686 | AN14: icici index | AO14: 3872421.9 | AQ14: icici index | AR14: 3764793 | AT14: hdfc midcap | AU14: 839420.1 | AW14: hdfc midcap | AX14: 878070.85 | AZ14: hdfc midcap | BA14: 896086.2 | BC14: hdfc midcap | BD14: 898313.84 | BF14: hdfc midcap | BG14: 898979
A15: Zerodha Cash | B15: 228388.64 | D15: Zerodha Cash | E15: 661661.17 | G15: Zerodha Cash | H15: 811000 | J15: Zerodha Cash | K15: 496612.21 | M15: Zerodha Cash | N15: 16000 | P15: Zerodha Cash | Q15: 88000 | S15: Zerodha Cash | T15: 238126 | V15: Zerodha Cash | W15: 437579.32 | Y15: Zerodha Cash | Z15: 500000 | AB15: Zerodha Cash | AC15: 600000 | AE15: Zerodha Cash | AF15: 675000 | AH15: Zerodha Cash | AI15: 413934 | AK15: Zerodha Cash | AL15: 567264 | AN15: Zerodha Cash | AO15: 65000 | AQ15: Zerodha Cash | AR15: 250000 | AT15: hdfc index | AU15: 3772585.2 | AW15: hdfc index | AX15: 3946120.4 | AZ15: hdfc index | BA15: 4021020.2 | BC15: hdfc index | BD15: 4016339.8 | BF15: hdfc index | BG15: 3914849
A16: Sbi | B16: 641244 | D16: Sbi | E16: 745656 | G16: Sbi | H16: 883516 | J16: Sbi | K16: 934309 | M16: Sbi | N16: 232186 | P16: Sbi | Q16: 343077 | S16: Sbi | T16: 724365 | V16: Sbi | W16: 688648.09 | Y16: Sbi | Z16: 1006347 | AB16: Sbi | AC16: 1309157 | AE16: Sbi | AF16: 567173 | AH16: Sbi | AI16: 400936 | AK16: Sbi | AL16: 561112 | AN16: Sbi | AO16: 19792 | AQ16: Sbi | AR16: 240500 | AT16: icici index | AU16: 3746509.6 | AW16: icici index | AX16: 3918749.2 | AZ16: icici index | BA16: 3993218.9 | BC16: icici index | BD16: 3988655 | BF16: icici index | BG16: 3887785
A17: Hdfc | B17: 300 | D17: Hdfc | E17: 300 | G17: Hdfc | H17: 400 | J17: Hdfc | K17: 880878 | M17: Hdfc | N17: 4682 | P17: Hdfc | Q17: 500 | S17: Hdfc | T17: 706 | V17: Hdfc | W17: 1006 | Y17: Hdfc | Z17: 790.4 | AB17: Hdfc | AC17: 2060 | AE17: Hdfc | AF17: 6094 | AH17: Hdfc | AI17: 6287 | AK17: Hdfc | AL17: 755 | AN17: Hdfc | AO17: 32602 | AQ17: Hdfc | AR17: 1600 | AT17: Zerodha Cash | AU17: 236000 | AW17: Zerodha Cash | AX17: 340000 | AZ17: Zerodha Cash | BA17: 126000 | BC17: Zerodha Cash | BD17: 173000 | BF17: Zerodha Cash | BG17: 152000 | BI17: Equity | BJ17: =BJ2+BJ3+BJ6+BJ7+BJ4+BJ5 -> 11428468
A18: Citi | B18: 102530 | D18: Citi | E18: 102530 | G18: Citi | H18: 102000 | J18: Axis | K18: 102484 | M18: Axis | N18: 102245 | P18: Axis | Q18: 101998 | S18: Axis | T18: 101998 | V18: Axis | W18: 102759 | Y18: Axis | Z18: 102757 | AB18: Axis | AC18: 102607 | AE18: Axis | AF18: 102475 | AH18: Axis | AI18: 102475 | AK18: Axis | AL18: 102475 | AN18: Axis | AO18: 103185 | AQ18: Axis | AR18: 102000 | AT18: Sbi | AU18: 129248 | AW18: Sbi | AX18: 661449 | AZ18: Sbi | BA18: 96883 | BC18: Sbi | BD18: 4000 | BF18: Sbi | BG18: 221432 | BI18: PF | BJ18: =651717+358128 -> 1009845
A19: crypto | B19: 480000 | D19: crypto | E19: 480000 | G19: crypto | H19: 480000 | J19: crypto | K19: 480000 | M19: crypto | N19: 480000 | P19: crypto | Q19: 480000 | S19: crypto | T19: 0 | V19: crypto | W19: 0 | Y19: crypto | Z19: 0 | AB19: crypto | AC19: 0 | AE19: crypto | AF19: 0 | AH19: crypto | AI19: 0 | AK19: crypto | AL19: 0 | AN19: crypto | AO19: 0 | AQ19: crypto | AR19: 0 | AT19: Hdfc | AU19: 290404 | AW19: Hdfc | AX19: 900 | AZ19: Hdfc | BA19: 800 | BC19: Hdfc | BD19: =386626-447905-235000 -> -296279 | BF19: Hdfc | BG19: 193301 | BI19: Free | BJ19: =BJ8+BJ9+BJ10+BJ11 -> 669745
A20: given by parents | B20: =8075000+70000+3700000 -> 11845000 | C20: =B20*7% -> 829150 | D20: given by parents | E20: =8075000+70000+3700000 -> 11845000 | G20: given by parents | H20: =8075000+70000+3700000 -> 11845000 | J20: given by parents | K20: =8075000+70000+3700000+1550000 -> 13395000 | M20: given by mummy | N20: =8075000+70000+3700000+1550000-2000000-1550000 -> 9845000 | P20: given by mummy | Q20: =8075000+70000+3700000+1550000-2000000-1550000 -> 9845000 | S20: given by mummy | T20: =8075000+70000+3700000+1550000-2000000-1550000 -> 9845000 | V20: given by mummy | W20: =8075000+70000+3700000+1550000-2000000-1550000 -> 9845000 | Y20: given by mummy | Z20: =8075000+70000+3700000+1550000-2000000-1550000 -> 9845000 | AB20: given by mummy | AC20: =8075000+70000+3700000+1550000-2000000-1550000 -> 9845000 | AE20: given by mummy | AF20: =8075000+70000+3700000+1550000-2000000-1550000 -> 9845000 | AH20: given by mummy | AI20: =8075000+70000+3700000+1550000-2000000-1550000 -> 9845000 | AK20: given by mummy | AL20: =8075000+70000+3700000+1550000-2000000-1550000 -> 9845000 | AN20: given by mummy | AO20: =8075000+70000+3700000+1550000-2000000-1550000 -> 9845000 | AQ20: given by mummy | AR20: =8075000+70000+3700000+1550000-2000000-1550000 -> 9845000 | AT20: Axis | AU20: 75900 | AW20: Axis | AX20: 75700 | AZ20: Axis | BA20: 75000 | BC20: Axis | BD20: 75000 | BF20: Amruta HDFC | BG20: 146392 | BI20: Kohinoor flat | BJ20: 5932760
A21: My Total | B21: =SUM(B9:B19)-B20-B12-B13-B14 -> 12561939 | D21: My Total | E21: =SUM(E9:E19)-E20-E12-E13-E14 -> 13187747 | G21: My Total | H21: =SUM(H9:H19)-H20-H12-H13-H14 -> 14270030 | J21: My Total | K21: =SUM(K9:K19)-K20-K12-K13-K14 -> 13757824 | M21: My Total | N21: =SUM(N9:N19)-N20-N12-N13-N14 -> 13794967 | P21: My Total | Q21: =SUM(Q9:Q19)-Q20-Q12-Q13-Q14 -> 13061939 | S21: My Total | T21: =SUM(T9:T19)-T20-T12-T13-T14 -> 13388907 | V21: My Total | W21: =SUM(W9:W19)-W20-W12-W13-W14 -> 13407292 | Y21: My Total | Z21: =SUM(Z9:Z19)-Z20-Z12-Z13-Z14 -> 13799623 | AB21: My Total | AC21: =SUM(AC9:AC19)-AC20-AC12-AC13-AC14 -> 13715533 | AE21: My Total | AF21: =SUM(AF9:AF19)-AF20-AF12-AF13-AF14 -> 14632484 | AH21: My Total | AI21: =SUM(AI9:AI19)-AI20-AI12-AI13-AI14 -> 16193298 | AK21: My Total | AL21: =SUM(AL9:AL19)-AL20-AL12-AL13-AL14 -> 16846468 | AN21: My Total | AO21: =SUM(AO9:AO19)-AO20-AO12-AO13-AO14 -> 18021391 | AQ21: My Total | AR21: =SUM(AR9:AR19)-AR20-AR12-AR13-AR14 -> 18161954 | AT21: crypto | AU21: 0 | AW21: crypto | AX21: 0 | AZ21: crypto | BA21: 0 | BC21: crypto | BD21: 0 | BF21: crypto | BG21: 0 | BI21: A6 401 | BJ21: 17800000
AT22: given by mummy | AU22: =8075000+70000+3700000+1550000-2000000-1550000 -> 9845000 | AW22: given by mummy | AX22: =8075000+70000+3700000+1550000-2000000-1550000 -> 9845000 | AZ22: given by mummy | BA22: =8075000+70000+3700000+1550000-2000000-1550000 -> 9845000 | BC22: given by mummy | BD22: =8075000+70000+3700000+1550000-2000000-1550000 -> 9845000 | BF22: given by mummy | BG22: 0 | BI22: India Total | BJ22: =SUM(BJ17:BJ21) -> 36840818
A23: aniket pf | B23: 578013 | C23: amruta pf | D23: 287311 | E23: 45749 | F23: total | G23: =B23+D23 -> 865324 | V23: Equity | W23: =W11 -> 9512605 | Y23: Equity | Z23: =Z11 -> 9455702.2 | AB23: Equity | AC23: =AC11 -> 8902654.4 | AE23: Equity | AF23: =AF11 -> 10361984 | AH23: Equity | AI23: =AI11 -> 10758562 | AK23: Equity | AL23: =AL11 -> 11024068 | AN23: Equity | AO23: =AO11 -> 11374078 | AQ23: Equity | AR23: =AR11 -> 11058343 | AT23: My Total | AU23: =SUM(AU9:AU21)-AU22-AU12-AU15-AU16-AU13-AU14 -> 18726053 | AW23: My Total | AX23: =SUM(AX9:AX21)-AX22-AX12-AX15-AX16-AX13-AX14 -> 19606115 | AZ23: My Total | BA23: =SUM(BA9:BA21)-BA22-BA12-BA15-BA16-BA13-BA14 -> 19019109 | BC23: My Total | BD23: =SUM(BD9:BD21)-BD22-BD12-BD15-BD16-BD13-BD14 -> 18841605 | BF23: My Total | BG23: =SUM(BG9:BG21)-BG22-BG12-BG15-BG16-BG13-BG14 -> 25745071
V24: Fixed Income | W24: =W9-W20 -> 2664694.2 | Y24: Fixed Income | Z24: =Z9-Z20 -> 2734026.7 | AB24: Fixed Income | AC24: =AC9-AC20 -> 2799054.5 | AE24: Fixed Income | AF24: =AF9-AF20 -> 2919758.2 | AH24: Fixed Income | AI24: =AI9-AI20 -> 4511104.1 | AK24: Fixed Income | AL24: =AL9-AL20 -> 4590794 | AN24: Fixed Income | AO24: =AO9-AO20 -> 6426734.5 | AQ24: Fixed Income | AR24: =AR9-AR20 -> 6509510.7
A25: T-bills - Received Rs. 750000 (invested 701475) which is Rs 48525 profit (7500 * (100 - 93.53)) on 2 Nov 2023 | V25: Free | W25: =W15+W16+W17+W18 -> 1229992.4 | Y25: Free | Z25: =Z15+Z16+Z17+Z18 -> 1609894.4 | AB25: Free | AC25: =AC15+AC16+AC17+AC18 -> 2013824 | AE25: Free | AF25: =AF15+AF16+AF17+AF18 -> 1350742 | AH25: Free | AI25: =AI15+AI16+AI17+AI18 -> 923632 | AK25: Free | AL25: =AL15+AL16+AL17+AL18 -> 1231606 | AN25: Free | AO25: =AO15+AO16+AO17+AO18 -> 220579 | AQ25: Free | AR25: =AR15+AR16+AR17+AR18 -> 594100 | AT25: Equity | AU25: =AU11 -> 11349935 | AW25: Equity | AX25: =AX11 -> 11800330 | AZ25: Equity | BA25: =BA11 -> 11915366 | BC25: Equity | BD25: =BD11 -> 11854533 | BF25: Equity | BG25: =BG11 -> 11428468
A26: Bond - Received Rs. 940000 (9400 * 100) on Maturity 27 June 2024. Interest received on Dec 27 and June 27 of Rs 31443 each. Loss was 11450 (951450 - 940000) | V26: Real estate | W26: 3330645 | Y26: Real estate | Z26: 3330645 | AB26: Real estate | AC26: 3330645 | AE26: Real estate | AF26: 3330645 | AH26: Real estate | AI26: 3330645 | AK26: Real estate | AL26: 3330645 | AN26: Real estate | AO26: 3330645 | AQ26: Real estate | AR26: 3330645 | AT26: Fixed Income | AU26: =AU9-AU22 -> 6644565.8 | AW26: Fixed Income | AX26: =AX9-AX22 -> 6727735.2 | AZ26: Fixed Income | BA26: =BA9-BA22 -> 6805060 | BC26: Fixed Income | BD26: =BD9-BD22 -> 7031350.7 | BF26: Fixed Income | BG26: =BG9 -> 13603478
V27: Total | W27: =SUM(W23:W26) -> 16737937 | Y27: Total | Z27: =SUM(Z23:Z26) -> 17130268 | AB27: Total | AC27: =SUM(AC23:AC26) -> 17046178 | AE27: Total | AF27: =SUM(AF23:AF26) -> 17963129 | AH27: Total | AI27: =SUM(AI23:AI26) -> 19523943 | AK27: Total | AL27: =SUM(AL23:AL26) -> 20177113 | AN27: Total | AO27: =SUM(AO23:AO26) -> 21352036 | AQ27: Total | AR27: =SUM(AR23:AR26) -> 21492599 | AT27: Free | AU27: =AU17+AU18+AU19+AU20 -> 731552 | AW27: Free | AX27: =AX17+AX18+AX19+AX20 -> 1078049 | AZ27: Free | BA27: =BA17+BA18+BA19+BA20 -> 298683 | BC27: Free | BD27: =BD17+BD18+BD19+BD20 -> -44279 | BF27: Free | BG27: =BG17+BG18+BG19+BG20 -> 713125 | BI27: UAE Total | BJ27: =1*25 -> 25
A28: Date | B28: Total funds | C28: tata mmf | D28: amruta tata | E28: amruta absl | F28: uti liquid | G28: sbi liquid | H28: sbi savings | I28: increase per day | AT28: Real estate | AU28: 3330645 | AW28: Real estate | AX28: 3330645 | AZ28: Real estate | BA28: 4589045 | BC28: Real estate | BD28: 5484855 | BF28: Kohinoor flat | BG28: 5932760
A29: 45139 | B29: =SUM(C29:H29) -> 10372881 | D29: 1350658 | E29: 861632 | F29: 3307408 | G29: 4853183 | M29: Amruta: | AT29: Total | AU29: =SUM(AU25:AU28) -> 22056698 | AW29: Total | AX29: =SUM(AX25:AX28) -> 22936760 | AZ29: Total | BA29: =SUM(BA25:BA28) -> 23608154 | BC29: Total | BD29: =SUM(BD25:BD28) -> 24326460 | BF29: A6 401 | BG29: 17800000 | BI29: Total | BJ29: =BJ22+BJ27 -> 36840843
A30: 45143 | B30: =SUM(C30:H30) -> 10380708 | D30: 1351582 | E30: 862216 | F30: 3309974 | G30: 4856936 | I30: =(B30-B$29)/(A30-A$29) -> 1956.75 | M30: CTC | N30: 1451566 | AI30: Flexi cap | AJ30: Mid cap | AK30: Hybrid | BF30: Total | BG30: =SUM(BG25:BG29) -> 49477831
A31: 45145 | B31: =SUM(C31:H31) -> 10384397 | D31: 1352041 | E31: 862512 | F31: 3311171 | G31: 4858673 | I31: =(B31-B$29)/(A31-A$29) -> 1919.3333 | M31: PF | N31: 41328 | AI31: PP | AJ31: MO | AK31: HDFC Balanced Advantage | AN31: Flexi cap rolling returns
A32: 45149 | B32: =SUM(C32:H32) -> 10391027 | D32: 1352964 | E32: 863102 | F32: 3313236 | G32: 4861725 | I32: =(B32-B$29)/(A32-A$29) -> 1814.6 | M32: Gratuity | N32: 16566 | AI32: HDFC | AJ32: HDFC | AK32: SBI Equity Hybrid | AN32: https://www.advisorkhoj.com/mutual-funds-research/rolling-returns?category=Equity:%20Flexi%20Cap&schemes=Parag%20Parikh%20Flexi%20Cap%20Dir%20Gr,HDFC%20Flexi%20Cap%20Dir%20Gr,JM%20Flexi%20Cap%20Dir%20Gr,Motilal%20Oswal%20Flexi%20Cap%20Fund%20Dir%20Gr&start_date=10-09-2020&period=3%20Year
A33: 45155 | B33: =SUM(C33:H33) -> 10402237 | D33: 1354406 | E33: 864019 | F33: 3316859 | G33: 4866953 | I33: =(B33-B$29)/(A33-A$29) -> 1834.75 | M33: CTC-above | N33: =N30-N31-N32 -> 1393672 | P33: =N33-1200000 -> 193672 | Q33: =287000 -> 287000 | AI33: JM | AJ33: Nippon | AK33: Kotak Arbitrage
A34: 45160 | B34: =SUM(C34:H34) -> 10411575 | D34: 1355633 | E34: 864804 | F34: 3319866 | G34: 4871272 | I34: =(B34-B$29)/(A34-A$29) -> 1842.5714 | M34: Tax | N34: =90000+P34 -> 128734.4 | P34: =20%*P33 -> 38734.4 | Q34: =Q33*120% -> 344400 | AI34: MO | AJ34: Kotak | AK34: ICICI Balanced Advantage | AN34: Mid cap rolling returns
A35: 45169 | B35: =SUM(C35:H35) -> 10429162 | D35: 1357870 | E35: 866225 | F35: 3325457 | G35: 4879610 | I35: =(B35-B$29)/(A35-A$29) -> 1876.0333 | J35: =B35-B29 -> 56281 | M35: After Tax Yearly | N35: =N33-N34 -> 1264937.6 | Q35: =Q34-Q33 -> 57400 | AJ35: Edelweiss | AK35: SBI Arbitrage | AN35: https://www.advisorkhoj.com/mutual-funds-research/rolling-returns?category=Equity:%20Mid%20Cap&schemes=Edelweiss%20MidCap%20Dir%20Gr,Motilal%20Oswal%20Midcap%20Fund%20Dir%20Gr,HDFC%20Mid%20Cap%20Fund%20Gr%20Dir&start_date=10-09-2020&period=3%20Year
A36: 45170 | B36: =SUM(C36:H36) -> 10981184 | D36: 1358117 | E36: 866384 | F36: 3326115 | G36: 4880568 | H36: 550000 | M36: Monthly | N36: =N35/12 -> 105411.47 | Q36: =Q35/12 -> 4783.3333
A37: 45188 | B37: =SUM(C37:H37) -> 11019366 | D37: 1362764 | E37: 869345 | F37: 3337831 | G37: 4897726 | H37: 551700 | I37: =(B37-B$36)/(A37-A$36) -> 2121.2222 | J37: =B37-B36 -> 38182 | M37: Average Monthly with excess incentive | N37: =N36+Q36 -> 110194.8
A38: 45197 | B38: =SUM(C38:H38) -> 11035850 | D38: 1364761 | E38: 870618 | F38: 3342849 | G38: 4905013 | H38: 552609 | I38: =(B38-B$36)/(A38-A$36) -> 2024.6667 | J38: =B38-B36 -> 54666 | BG38: profit | BH38: tax | BI38: percent tax of capital
A39: 45199 | B39: =SUM(C39:H39) -> 11040837 | D39: 1365273 | E39: 870940 | F39: 3344436 | G39: 4907300 | H39: 552888 | I39: =(B39-B$36)/(A39-A$36) -> 2057 | J39: =B39-B36 -> 59653 | M39: Aniket | BD39: Antariksh bank | BE39: 2500000 | BH39: 0
A40: 45215 | B40: =SUM(C40:H40) -> 12424047 | D40: 1369317 | E40: 873501 | F40: 3354349 | G40: 4921779 | H40: 1905101 | N40: 3256546 | P40: Income tax slabs (Rs) | Q40: Income tax rate (%) | BD40: antariksh mf | BE40: 1591575 | BG40: -8400 | BH40: 0 | BI40: =BH40/BE40 -> 0 | BK40: yellow sum | BL40: my debt funds tax | BM40: others tax
...

Sheet month wise 2025-26
B1: April | D1: 21000000 | L1: June | N1: 21000000 | V1: August | X1: 21000000 | AG1: October | AI1: 21000000 | AQ1: December | AS1: 21000000 | BA1: February | BC1: 21000000
B2: week1 | D2: =C2*100/D$1 -> 0 | E2: =SUM(C2:C6) -> 42778 | F2: =E2*100/D1 -> 0.20370476 | G2: ani sal | H2: 161000 | L2: week1 | N2: =M2*100/N$1 -> 0 | O2: =SUM(M2:M6) -> 14334 | P2: =O2*100/N1 -> 0.068257143 | Q2: ani sal | R2: 0 | V2: week1 | W2: 1600 | X2: =W2*100/X$1 -> 0.0076190476 | Y2: =SUM(W2:W6) -> 22902 | Z2: =Y2*100/X1 -> 0.10905714 | AA2: ani sal | AB2: 209000 | AG2: week1 | AI2: =AH2*100/AI$1 -> 0 | AJ2: =SUM(AH2:AH6) -> 10330 | AK2: =AJ2*100/AI1 -> 0.049190476 | AL2: ani sal | AM2: 209000 | AQ2: week1 | AS2: =AR2*100/AS$1 -> 0 | AT2: =SUM(AR2:AR6) -> 20400 | AU2: =AT2*100/AS1 -> 0.097142857 | AV2: ani sal | AW2: 209000 | BA2: week1 | BC2: =BB2*100/BC$1 -> 0 | BD2: =SUM(BB2:BB6) -> -297120 | BE2: =BD2*100/BC1 -> -1.4148571 | BF2: ani sal | BG2: 209000
C3: 25900 | D3: =C3*100/D$1 -> 0.12333333 | G3: amr sal | H3: 170000 | M3: 6700 | N3: =M3*100/N$1 -> 0.031904762 | Q3: amr sal | R3: 90000 | W3: 7676 | X3: =W3*100/X$1 -> 0.036552381 | AA3: amr sal | AB3: 86000 | AI3: =AH3*100/AI$1 -> 0 | AL3: amr sal | AM3: 86000 | AR3: 10000 | AS3: =AR3*100/AS$1 -> 0.047619048 | AV3: amr sal | AW3: 86000 | BB3: 5792 | BC3: =BB3*100/BC$1 -> 0.027580952 | BF3: amr sal | BG3: 86000
D4: =C4*100/D$1 -> 0 | G4: p | H4: =C29 -> -633525 | N4: =M4*100/N$1 -> 0 | Q4: p | R4: =M29 -> -17601 | X4: =W4*100/X$1 -> 0 | AA4: p | AB4: =W29 -> 98079 | AI4: =AH4*100/AI$1 -> 0 | AL4: p | AM4: =AH29 -> 103759 | AR4: 3500 | AS4: =AR4*100/AS$1 -> 0.016666667 | AV4: p | AW4: =AR29 -> 130435 | BB4: =-315659-853 -> -316512 | BC4: =BB4*100/BC$1 -> -1.5072 | BF4: p | BG4: =BB29 -> -226120
C5: 16878 | D5: =C5*100/D$1 -> 0.080371429 | G5: nf strategy | H5: =0 -> 0 | M5: 7634 | N5: =M5*100/N$1 -> 0.036352381 | Q5: nf strategy | R5: 34368 | W5: 12147 | X5: =W5*100/X$1 -> 0.057842857 | AA5: nf strategy | AB5: 0 | AH5: 10330 | AI5: =AH5*100/AI$1 -> 0.049190476 | AL5: nf strategy | AM5: 0 | AR5: 6900 | AS5: =AR5*100/AS$1 -> 0.032857143 | AV5: nf strategy | AW5: 0 | BB5: 13600 | BC5: =BB5*100/BC$1 -> 0.064761905 | BF5: nf strategy | BG5: 0
D6: =C6*100/D$1 -> 0 | G6: int | H6: 80700 | I6: market total | J6: =H4+H5+H6 -> -552825 | N6: =M6*100/N$1 -> 0 | Q6: int | R6: 65000 | S6: market total | T6: =R4+R5+R6 -> 81767 | W6: 1479 | X6: =W6*100/X$1 -> 0.0070428571 | AA6: int | AB6: 65000 | AC6: market total | AD6: =AB4+AB5+AB6 -> 163079 | AI6: =AH6*100/AI$1 -> 0 | AL6: int | AM6: 65000 | AN6: market total | AO6: =AM4+AM5+AM6 -> 168759 | AS6: =AR6*100/AS$1 -> 0 | AV6: int | AW6: 65000 | AX6: market total | AY6: =AW4+AW5+AW6 -> 195435 | BC6: =BB6*100/BC$1 -> 0 | BF6: int | BG6: 65000 | BH6: market total | BI6: =BG4+BG5+BG6 -> -161120
B7: week2 | D7: =C7*100/D$1 -> 0 | E7: =SUM(C7:C11) -> -746763 | F7: =E7*100/D1 -> -3.5560143 | G7: total | H7: =SUM(H2:H6) -> -221825 | L7: week2 | N7: =M7*100/N$1 -> 0 | O7: =SUM(M7:M11) -> 13640 | P7: =O7*100/N1 -> 0.064952381 | Q7: total | R7: =SUM(R2:R6) -> 171767 | V7: week2 | X7: =W7*100/X$1 -> 0 | Y7: =SUM(W7:W11) -> 24952 | Z7: =Y7*100/X1 -> 0.11881905 | AA7: total | AB7: =SUM(AB2:AB6) -> 458079 | AG7: week2 | AI7: =AH7*100/AI$1 -> 0 | AJ7: =SUM(AH7:AH11) -> 25349 | AK7: =AJ7*100/AI1 -> 0.12070952 | AL7: total | AM7: =SUM(AM2:AM6) -> 463759 | AQ7: week2 | AR7: =9738-258 -> 9480 | AS7: =AR7*100/AS$1 -> 0.045142857 | AT7: =SUM(AR7:AR11) -> 45825 | AU7: =AT7*100/AS1 -> 0.21821429 | AV7: total | AW7: =SUM(AW2:AW6) -> 490435 | BA7: week2 | BC7: =BB7*100/BC$1 -> 0 | BD7: =SUM(BB7:BB11) -> 24700 | BE7: =BD7*100/BC1 -> 0.11761905 | BF7: total | BG7: =SUM(BG2:BG6) -> 133880
C8: -764031 | D8: =C8*100/D$1 -> -3.6382429 | M8: 6577 | N8: =M8*100/N$1 -> 0.031319048 | W8: 13250 | X8: =W8*100/X$1 -> 0.063095238 | AH8: 12283 | AI8: =AH8*100/AI$1 -> 0.058490476 | AR8: 20000 | AS8: =AR8*100/AS$1 -> 0.095238095 | BB8: 15700 | BC8: =BB8*100/BC$1 -> 0.074761905
C9: 17268 | D9: =C9*100/D$1 -> 0.082228571 | N9: =M9*100/N$1 -> 0 | X9: =W9*100/X$1 -> 0 | AI9: =AH9*100/AI$1 -> 0 | AR9: 4300 | AS9: =AR9*100/AS$1 -> 0.02047619 | BC9: =BB9*100/BC$1 -> 0
D10: =C10*100/D$1 -> 0 | M10: 7063 | N10: =M10*100/N$1 -> 0.033633333 | W10: 11702 | X10: =W10*100/X$1 -> 0.05572381 | AH10: 13066 | AI10: =AH10*100/AI$1 -> 0.062219048 | AR10: 12300 | AS10: =AR10*100/AS$1 -> 0.058571429 | BB10: 9000 | BC10: =BB10*100/BC$1 -> 0.042857143
D11: =C11*100/D$1 -> 0 | N11: =M11*100/N$1 -> 0 | X11: =W11*100/X$1 -> 0 | AI11: =AH11*100/AI$1 -> 0 | AR11: -255 | AS11: =AR11*100/AS$1 -> -0.0012142857 | BC11: =BB11*100/BC$1 -> 0
B12: week3 | D12: =C12*100/D$1 -> 0 | E12: =SUM(C12:C16) -> 26299 | F12: =E12*100/D1 -> 0.12523333 | L12: week3 | N12: =M12*100/N$1 -> 0 | O12: =SUM(M12:M16) -> 23868 | P12: =O12*100/N1 -> 0.11365714 | V12: week3 | W12: 1022 | X12: =W12*100/X$1 -> 0.0048666667 | Y12: =SUM(W12:W16) -> 17975 | Z12: =Y12*100/X1 -> 0.085595238 | AG12: week3 | AI12: =AH12*100/AI$1 -> 0 | AJ12: =SUM(AH12:AH16) -> 23380 | AK12: =AJ12*100/AI1 -> 0.11133333 | AQ12: week3 | AS12: =AR12*100/AS$1 -> 0 | AT12: =SUM(AR12:AR16) -> 29000 | AU12: =AT12*100/AS1 -> 0.13809524 | BA12: week3 | BC12: =BB12*100/BC$1 -> 0 | BD12: =SUM(BB12:BB16) -> 23500 | BE12: =BD12*100/BC1 -> 0.11190476
C13: 18858 | D13: =C13*100/D$1 -> 0.0898 | M13: 13430 | N13: =M13*100/N$1 -> 0.063952381 | W13: 7100 | X13: =W13*100/X$1 -> 0.033809524 | AH13: 11600 | AI13: =AH13*100/AI$1 -> 0.055238095 | AN13: =C29 -> -633525 | AR13: 10000 | AS13: =AR13*100/AS$1 -> 0.047619048 | BB13: 14500 | BC13: =BB13*100/BC$1 -> 0.069047619
D14: =C14*100/D$1 -> 0 | N14: =M14*100/N$1 -> 0 | X14: =W14*100/X$1 -> 0 | AH14: 1800 | AI14: =AH14*100/AI$1 -> 0.0085714286 | AN14: =C61 -> 109427 | AS14: =AR14*100/AS$1 -> 0 | BC14: =BB14*100/BC$1 -> 0
C15: 7441 | D15: =C15*100/D$1 -> 0.035433333 | M15: 10438 | N15: =M15*100/N$1 -> 0.049704762 | W15: 9853 | X15: =W15*100/X$1 -> 0.046919048 | AH15: 9980 | AI15: =AH15*100/AI$1 -> 0.04752381 | AN15: =M29 -> -17601 | AR15: 10000 | AS15: =AR15*100/AS$1 -> 0.047619048 | BB15: 9000 | BC15: =BB15*100/BC$1 -> 0.042857143
D16: =C16*100/D$1 -> 0 | N16: =M16*100/N$1 -> 0 | X16: =W16*100/X$1 -> 0 | AI16: =AH16*100/AI$1 -> 0 | AN16: =M61 -> 102823 | AR16: 9000 | AS16: =AR16*100/AS$1 -> 0.042857143 | BC16: =BB16*100/BC$1 -> 0
B17: week4 | D17: =C17*100/D$1 -> 0 | E17: =SUM(C17:C21) -> 26044 | F17: =E17*100/D1 -> 0.12401905 | L17: week4 | N17: =M17*100/N$1 -> 0 | O17: =SUM(M17:M21) -> -69443 | P17: =O17*100/N1 -> -0.33068095 | V17: week4 | W17: 4504 | X17: =W17*100/X$1 -> 0.021447619 | Y17: =SUM(W17:W21) -> 32250 | Z17: =Y17*100/X1 -> 0.15357143 | AG17: week4 | AH17: 8850 | AI17: =AH17*100/AI$1 -> 0.042142857 | AJ17: =SUM(AH17:AH21) -> 19650 | AK17: =AJ17*100/AI1 -> 0.093571429 | AN17: =W29 -> 98079 | AQ17: week4 | AS17: =AR17*100/AS$1 -> 0 | AT17: =SUM(AR17:AR21) -> 24080 | AU17: =AT17*100/AS1 -> 0.11466667 | BA17: week4 | BC17: =BB17*100/BC$1 -> 0 | BD17: =SUM(BB17:BB21) -> 22800 | BE17: =BD17*100/BC1 -> 0.10857143
C18: 10621 | D18: =C18*100/D$1 -> 0.05057619 | M18: =11645-114 -> 11531 | N18: =M18*100/N$1 -> 0.054909524 | W18: 10608 | X18: =W18*100/X$1 -> 0.050514286 | AI18: =AH18*100/AI$1 -> 0 | AN18: =W61 -> 107266 | AR18: 10600 | AS18: =AR18*100/AS$1 -> 0.05047619 | BB18: 14000 | BC18: =BB18*100/BC$1 -> 0.066666667
D19: =C19*100/D$1 -> 0 | N19: =M19*100/N$1 -> 0 | X19: =W19*100/X$1 -> 0 | AI19: =AH19*100/AI$1 -> 0 | AN19: =AH29 -> 103759 | AR19: 6300 | AS19: =AR19*100/AS$1 -> 0.03 | BC19: =BB19*100/BC$1 -> 0
C20: 15423 | D20: =C20*100/D$1 -> 0.073442857 | M20: -80974 | N20: =M20*100/N$1 -> -0.38559048 | W20: 17138 | X20: =W20*100/X$1 -> 0.081609524 | AH20: 10800 | AI20: =AH20*100/AI$1 -> 0.051428571 | AN20: =AH61 -> 86250 | AR20: 7180 | AS20: =AR20*100/AS$1 -> 0.034190476 | BB20: 8800 | BC20: =BB20*100/BC$1 -> 0.041904762
D21: =C21*100/D$1 -> 0 | N21: =M21*100/N$1 -> 0 | X21: =W21*100/X$1 -> 0 | AI21: =AH21*100/AI$1 -> 0 | AN21: =AR29 -> 130435 | AS21: =AR21*100/AS$1 -> 0 | AX21: 1000 | AY21: 2.5 | AZ21: =AX21*AY21 -> 2500 | BC21: =BB21*100/BC$1 -> 0
B22: week5 | D22: =C22*100/D$1 -> 0 | E22: =SUM(C22:C26) -> 18117 | F22: =E22*100/D1 -> 0.086271429 | L22: week5 | N22: =M22*100/N$1 -> 0 | O22: =SUM(M22:M26) -> 0 | P22: =O22*100/N1 -> 0 | V22: week5 | X22: =W22*100/X$1 -> 0 | Y22: =SUM(W22:W26) -> 0 | Z22: =Y22*100/X1 -> 0 | AG22: week5 | AI22: =AH22*100/AI$1 -> 0 | AJ22: =SUM(AH22:AH26) -> 25050 | AK22: =AJ22*100/AI1 -> 0.11928571 | AN22: =AR61 -> 103599 | AQ22: week5 | AS22: =AR22*100/AS$1 -> 0 | AT22: =SUM(AR22:AR26) -> 11130 | AU22: =AT22*100/AS1 -> 0.053 | AX22: 600 | AY22: 3.5 | AZ22: =AX22*AY22 -> 2100 | BA22: week5 | BC22: =BB22*100/BC$1 -> 0 | BD22: =SUM(BB22:BB26) -> 0 | BE22: =BD22*100/BC1 -> 0
C23: 7476 | D23: =C23*100/D$1 -> 0.0356 | N23: =M23*100/N$1 -> 0 | X23: =W23*100/X$1 -> 0 | AH23: 16000 | AI23: =AH23*100/AI$1 -> 0.076190476 | AN23: =BB29 -> -226120 | AR23: =1080+2220+1620+1350+4860 -> 11130 | AS23: =AR23*100/AS$1 -> 0.053 | AX23: 600 | AY23: 3.35 | AZ23: =AX23*AY23 -> 2010 | BC23: =BB23*100/BC$1 -> 0
C24: 10641 | D24: =C24*100/D$1 -> 0.050671429 | N24: =M24*100/N$1 -> 0 | X24: =W24*100/X$1 -> 0 | AH24: 1200 | AI24: =AH24*100/AI$1 -> 0.0057142857 | AN24: =BB61 -> 23540 | AS24: =AR24*100/AS$1 -> 0 | AX24: 1000 | AY24: 2.3 | AZ24: =AX24*AY24 -> 2300 | BC24: =BB24*100/BC$1 -> 0
D25: =C25*100/D$1 -> 0 | N25: =M25*100/N$1 -> 0 | X25: =W25*100/X$1 -> 0 | AH25: 7850 | AI25: =AH25*100/AI$1 -> 0.037380952 | AS25: =AR25*100/AS$1 -> 0 | AZ25: =SUM(AZ21:AZ24)-106 -> 8804 | BC25: =BB25*100/BC$1 -> 0
D26: =C26*100/D$1 -> 0 | N26: =M26*100/N$1 -> 0 | X26: =W26*100/X$1 -> 0 | AI26: =AH26*100/AI$1 -> 0 | AN26: =SUM(AN13:AN25) -> -12068 | AS26: =AR26*100/AS$1 -> 0 | BC26: =BB26*100/BC$1 -> 0
C29: =SUM(C2:C27) -> -633525 | M29: =SUM(M2:M27) -> -17601 | W29: =SUM(W2:W27) -> 98079 | AH29: =SUM(AH2:AH27) -> 103759 | AR29: =SUM(AR2:AR27) -> 130435 | BB29: =SUM(BB2:BB27) -> -226120
B30: % return | C30: =C29*100/D$1 -> -3.0167857 | L30: % return | M30: =M29*100/N$1 -> -0.083814286 | V30: % return | W30: =W29*100/X$1 -> 0.46704286 | AG30: % return | AH30: =AH29*100/AI$1 -> 0.49409048 | AQ30: % return | AR30: =AR29*100/AS$1 -> 0.62111905 | BA30: % return | BB30: =BB29*100/BC$1 -> -1.0767619
B31: % return with others | C31: =((C29*100)+(H5*100)+(H6*100))/D$1 -> -2.6325 | L31: % return with others | M31: =((M29*100)+(R5*100)+(R6*100))/N$1 -> 0.38936667 | V31: % return with others | W31: =((W29*100)+(AB5*100)+(AB6*100))/X$1 -> 0.77656667 | AG31: % return with others | AH31: =((AH29*100)+(AM5*100)+(AM6*100))/AI$1 -> 0.80361429 | AQ31: % return with others | AR31: =((AR29*100)+(AW5*100)+(AW6*100))/AS$1 -> 0.93064286 | BA31: % return with others | BB31: =((BB29*100)+(BG5*100)+(BG6*100))/BC$1 -> -0.7672381
B33: May | D33: 21000000 | L33: July | N33: 21000000 | V33: September | X33: 21000000 | AG33: November | AI33: 21000000 | AQ33: January | AS33: 21000000 | BA33: March | BC33: 21000000
B34: week1 | D34: =C34*100/D$33 -> 0 | E34: =SUM(C34:C38) -> 23308 | F34: =E34*100/D33 -> 0.11099048 | G34: ani sal | H34: 119607 | L34: week1 | N34: =M34*100/N$33 -> 0 | O34: =SUM(M34:M38) -> 25640 | P34: =O34*100/N33 -> 0.12209524 | Q34: ani sal | R34: 194000 | V34: week1 | X34: =W34*100/X$33 -> 0 | Y34: =SUM(W34:W38) -> 18364 | Z34: =Y34*100/X33 -> 0.087447619 | AA34: ani sal | AB34: 194000 | AG34: week1 | AI34: =AH34*100/AI$33 -> 0 | AJ34: =SUM(AH34:AH38) -> 23000 | AK34: =AJ34*100/AI33 -> 0.10952381 | AL34: ani sal | AM34: 194000 | AQ34: week1 | AS34: =AR34*100/AS$33 -> 0 | AT34: =SUM(AR34:AR38) -> 3050 | AU34: =AT34*100/AS33 -> 0.01452381 | AV34: ani sal | AW34: 194000 | BA34: week1 | BC34: =BB34*100/BC$33 -> 0 | BD34: =SUM(BB34:BB38) -> 23540 | BE34: =BD34*100/BC33 -> 0.11209524 | BF34: ani sal | BG34: 194000
C35: 10308 | D35: =C35*100/D$33 -> 0.049085714 | G35: amr sal | H35: 96000 | M35: 12000 | N35: =M35*100/N$33 -> 0.057142857 | Q35: amr sal | R35: 83000 | W35: 9458 | X35: =W35*100/X$33 -> 0.045038095 | AA35: amr sal | AB35: 83000 | AH35: 13800 | AI35: =AH35*100/AI$33 -> 0.065714286 | AL35: amr sal | AM35: 83000 | AS35: =AR35*100/AS$33 -> 0 | AV35: amr sal | AW35: 83000 | BB35: 11000 | BC35: =BB35*100/BC$33 -> 0.052380952 | BF35: amr sal | BG35: 83000
D36: =C36*100/D$33 -> 0 | G36: p | H36: =C61 -> 109427 | N36: =M36*100/N$33 -> 0 | Q36: p | R36: =M61 -> 102823 | X36: =W36*100/X$33 -> 0 | AA36: p | AB36: =W61 -> 107266 | AI36: =AH36*100/AI$33 -> 0 | AL36: p | AM36: =AH61 -> 86250 | AS36: =AR36*100/AS$33 -> 0 | AV36: p | AW36: =AR61 -> 103599 | BC36: =BB36*100/BC$33 -> 0 | BF36: p | BG36: =BB61 -> 23540
C37: 13000 | D37: =C37*100/D$33 -> 0.061904762 | G37: nf strategy | H37: -16113 | M37: 11100 | N37: =M37*100/N$33 -> 0.052857143 | Q37: nf strategy | R37: 0 | W37: 8906 | X37: =W37*100/X$33 -> 0.042409524 | AA37: nf strategy | AB37: 0 | AH37: 9200 | AI37: =AH37*100/AI$33 -> 0.043809524 | AL37: nf strategy | AM37: 0 | AR37: 3050 | AS37: =AR37*100/AS$33 -> 0.01452381 | AV37: nf strategy | AW37: 0 | BB37: 12540 | BC37: =BB37*100/BC$33 -> 0.059714286 | BF37: nf strategy | BG37: 0
D38: =C38*100/D$33 -> 0 | G38: int | H38: 79690 | I38: market total | J38: =H36+H37+H38 -> 173004 | M38: 2540 | N38: =M38*100/N$33 -> 0.012095238 | Q38: int | R38: 61000 | S38: market total | T38: =R36+R37+R38 -> 163823 | X38: =W38*100/X$33 -> 0 | AA38: int | AB38: 61000 | AC38: market total | AD38: =AB36+AB37+AB38 -> 168266 | AI38: =AH38*100/AI$33 -> 0 | AL38: int | AM38: 61000 | AN38: market total | AO38: =AM36+AM37+AM38 -> 147250 | AS38: =AR38*100/AS$33 -> 0 | AV38: int | AW38: 61000 | AX38: market total | AY38: =AW36+AW37+AW38 -> 164599 | BC38: =BB38*100/BC$33 -> 0 | BF38: int | BG38: 61000 | BH38: market total | BI38: =BG36+BG37+BG38 -> 84540
B39: week2 | D39: =C39*100/D$33 -> 0 | E39: =SUM(C39:C43) -> 9695 | F39: =E39*100/D33 -> 0.046166667 | G39: total | H39: =SUM(H34:H38) -> 388611 | L39: week2 | M39: 1200 | N39: =M39*100/N$33 -> 0.0057142857 | O39: =SUM(M39:M43) -> 14409 | P39: =O39*100/N33 -> 0.068614286 | Q39: total | R39: =SUM(R34:R38) -> 440823 | V39: week2 | X39: =W39*100/X$33 -> 0 | Y39: =SUM(W39:W43) -> 20600 | Z39: =Y39*100/X33 -> 0.098095238 | AA39: total | AB39: =SUM(AB34:AB38) -> 445266 | AG39: week2 | AI39: =AH39*100/AI$33 -> 0 | AJ39: =SUM(AH39:AH43) -> 21190 | AK39: =AJ39*100/AI33 -> 0.10090476 | AL39: total | AM39: =SUM(AM34:AM38) -> 424250 | AQ39: week2 | AS39: =AR39*100/AS$33 -> 0 | AT39: =SUM(AR39:AR43) -> 24258 | AU39: =AT39*100/AS33 -> 0.11551429 | AV39: total | AW39: =SUM(AW34:AW38) -> 441599 | BA39: week2 | BC39: =BB39*100/BC$33 -> 0 | BD39: =SUM(BB39:BB43) -> 0 | BE39: =BD39*100/BC33 -> 0 | BF39: total | BG39: =SUM(BG34:BG38) -> 361540
C40: 10990 | D40: =C40*100/D$33 -> 0.052333333 | M40: 6229 | N40: =M40*100/N$33 -> 0.029661905 | W40: 12000 | X40: =W40*100/X$33 -> 0.057142857 | AH40: 12000 | AI40: =AH40*100/AI$33 -> 0.057142857 | AR40: 7858 | AS40: =AR40*100/AS$33 -> 0.037419048 | BC40: =BB40*100/BC$33 -> 0
D41: =C41*100/D$33 -> 0 | N41: =M41*100/N$33 -> 0 | X41: =W41*100/X$33 -> 0 | AI41: =AH41*100/AI$33 -> 0 | AR41: 7780 | AS41: =AR41*100/AS$33 -> 0.037047619 | BC41: =BB41*100/BC$33 -> 0
C42: -1295 | D42: =C42*100/D$33 -> -0.0061666667 | M42: 6980 | N42: =M42*100/N$33 -> 0.033238095 | W42: 8600 | X42: =W42*100/X$33 -> 0.040952381 | AH42: 9190 | AI42: =AH42*100/AI$33 -> 0.043761905 | AR42: 8620 | AS42: =AR42*100/AS$33 -> 0.041047619 | BC42: =BB42*100/BC$33 -> 0
D43: =C43*100/D$33 -> 0 | N43: =M43*100/N$33 -> 0 | X43: =W43*100/X$33 -> 0 | AI43: =AH43*100/AI$33 -> 0 | AS43: =AR43*100/AS$33 -> 0 | BC43: =BB43*100/BC$33 -> 0
...

Sheet Agreement
M1: Plot: | R1: Aniket | S1: Mummy | AO1: 20% with indexation | AR1: 12.5% without indexation | AU1: 20% with indexation | AX1: 12.5% without indexation | BA1: 20% with indexation | BD1: 12.5% without indexation | BJ1: 12.5% without indexation | BM1: 12.5% without indexation
C2: Agreement | D2: 8531524 | G2: TDS | H2: 8531 | I2: Paid till now: | J2: Paid to builder | M2: Cleaning | N2: 40000 | P2: Mummy salary | R2: 3750 | Z2: Agreement | AA2: 8531532 | AI2: CG | AJ2: 19092500 | AL2: CG | AM2: 19092500 | AO2: CG | AP2: 19092500 | AR2: CG | AS2: 19750000 | AU2: CG | AV2: 19092500 | AX2: CG | AY2: 19750000 | BA2: CG | BB2: 19092500 | BD2: CG | BE2: 19750000 | BJ2: CG | BK2: 19750000 | BM2: CG | BN2: 19750000
C3: GST | D3: 426576 | E3: 0.05 | G3: Aniket | H3: =H2/2 -> 4265.5 | I3: =D4+D5 -> 541900 | M3: Fabricator for 2 boards | N3: =3000+4800 -> 7800 | P3: 215696 | R3: 1000 | T3: Exemption=CG*investment/netSaleConsideration | Z3: GST | AA3: =AA2*AB3 -> 426576.6 | AB3: 0.05 | AI3: Investment | AJ3: 13100000 | AL3: Investment | AM3: 4102000 | AO3: Land | AP3: 4102000 | AR3: Land | AS3: 4102000 | AU3: Land | AV3: 4102000 | AX3: Land | AY3: 4102000 | BA3: Land | BB3: 4102000 | BD3: Land | BE3: 4102000 | BJ3: Land | BK3: 4102400 | BM3: Land | BN3: 4102400
C4: Stamp duty | D4: 511900 | E4: 0.06 | G4: Amruta | H4: =H2/2 -> 4265.5 | I4: 16000 | M4: Painter for 2 boards | N4: 3600 | P4: 218696 | R4: 2000 | Z4: Stamp duty | AA4: =AA2*AB4 -> 511891.92 | AB4: 0.06 | AD4: Ready reckoner 4L per guntha | AI4: NetSaleConsideration | AJ4: 20000000 | AL4: NetSaleConsideration | AM4: 20000000 | AO4: Flat | AP4: 13100000 | AR4: Flat | AS4: 13100000 | AU4: Flat | AV4: 12811000 | AX4: Flat | AY4: 12811000 | BA4: Flat | BB4: 14500000 | BD4: Flat | BE4: 14500000 | BJ4: Flat | BK4: 12811000 | BM4: Flat | BN4: 12811000
C5: Registration | D5: 30000 | I5: 85315 | M5: Tempo for boards | N5: =700+600 -> 1300 | P5: 213296 | T5: CG | U5: 19092500 | W5: CG | X5: 19455500 | Z5: Registration | AA5: 30000 | AD5: Total 32L baazarbhaav | AI5: Exemption | AJ5: =AJ2*AJ3/AJ4 -> 12505588 | AL5: Exemption | AM5: =AM2*AM3/AM4 -> 3915871.8 | AO5: Total Invested | AP5: =AP4+AP3 -> 17202000 | AR5: Total Invested | AS5: =AS4+AS3 -> 17202000 | AU5: Total Invested | AV5: =AV4+AV3 -> 16913000 | AX5: Total Invested | AY5: =AY4+AY3 -> 16913000 | BA5: Total Invested | BB5: =BB4+BB3 -> 18602000 | BD5: Total Invested | BE5: =BE4+BE3 -> 18602000 | BJ5: Proportion | BK5: =BK2*BK4/20000000 -> 12650862 | BM5: Proportion | BN5: =BN2*BN4/20000000 -> 12650862
C6: Total | D6: =SUM(D2:D5) -> 9500000 | I6: 1511835 | P6: 215276 | T6: Investment | U6: 17500000 | W6: Investment | X6: 17500000 | Z6: Total | AA6: =SUM(AA2:AA5) -> 9500000.5 | AO6: Proportion | AP6: =AP2*AP5/20000000 -> 16421459 | AR6: Proportion | AS6: =AS2*AS5/20000000 -> 16986975 | AU6: Proportion | AV6: =AV2*AV5/20000000 -> 16145573 | AX6: Proportion | AY6: =AY2*AY5/20000000 -> 16701588 | BA6: Proportion | BB6: =BB2*BB5/20000000 -> 17757934 | BD6: Proportion | BE6: =BE2*BE5/20000000 -> 18369475 | BJ6: Total Invested | BK6: =BK5+BK3 -> 16753262 | BM6: Total Invested | BN6: =BN5+BN3 -> 16753262
I7: 25594 | N7: =SUM(N2:N5) -> 52700 | P7: 257852 | T7: NetSaleConsideration | U7: 20000000 | W7: NetSaleConsideration | X7: 20000000 | AI7: Total Exempt | AJ7: =AJ5+AM5 -> 16421459 | AO7: Remaining | AP7: =AP2-AP6 -> 2671040.8 | AR7: Remaining | AS7: =AS2-AS6 -> 2763025 | AU7: Remaining | AV7: =AV2-AV6 -> 2946927.4 | AX7: Remaining | AY7: =AY2-AY6 -> 3048412.5 | BA7: Remaining | BB7: =BB2-BB6 -> 1334565.8 | BD7: Remaining | BE7: =BE2-BE6 -> 1380525 | BJ7: Remaining | BK7: =BK2-BK6 -> 2996737.5 | BM7: Remaining | BN7: =BN2-BN6 -> 2996737.5
C8: Legal fees | D8: 16000 | I8: 600000 | P8: 289324 | Q8: =297+190 -> 487 | T8: Exemption | U8: =U5*U6/U7 -> 16705938 | W8: Exemption | X8: =X5*X6/X7 -> 17023562 | AI8: Remaining | AJ8: =AJ2-AJ7 -> 2671040.8 | AO8: Tax | AP8: =AP7*20% -> 534208.15 | AR8: Tax | AS8: =AS7*12.5% -> 345378.12 | AU8: Tax | AV8: =AV7*20% -> 589385.47 | AX8: Tax | AY8: =AY7*12.5% -> 381051.56 | BA8: Tax | BB8: =BB7*20% -> 266913.15 | BD8: Tax | BE8: =BE7*12.5% -> 172565.62 | BJ8: Tax | BK8: =BK7*12.5% -> 374592.19 | BM8: Tax | BN8: =BN7*12.5% -> 374592.19
I9: 400000 | P9: 2080 | T9: RemainingFromSale | U9: =U7-U8 -> 3294062.5 | W9: RemainingFromSale | X9: =X7-X8 -> 2976437.5 | Z9: TDS | AA9: =AA2*AB9 -> 85315.32 | AB9: 0.01 | AD9: Mama sells vrindavan flat for 80L | AL9: =19750000-AJ7 -> 3328540.8
D10: Amount | E10: GST | F10: TDS | G10: Amount without TDS | I10: 75000 | P10: 1560 | Y10: =X5*12500000/X7 -> 12159688 | Z10: Balance agreement | AA10: =AA2-AA9 -> 8446216.7 | AD10: I sell PI flat to Mama for 80L. Balance 30L to receive from Mama/Nana | AL10: =AJ8*20% -> 534208.15 | AO10: Invest in Bonds | AP10: 2675000 | AR10: Invest in Bonds | AS10: 2770000 | AU10: Invest in Bonds | AV10: 2960000 | AX10: Invest in Bonds | AY10: 3065000 | BA10: Invest in Bonds | BB10: 1340000 | BD10: Invest in Bonds | BE10: 1390000 | BJ10: Invest in Bonds | BK10: 2996737.5 | BM10: Invest in Bonds | BN10: 2996737.5
C11: 0.1 | D11: 853152 | E11: 42658 | F11: 8532 | G11: =D11+E11-F11 -> 887278 | I11: 75000 | K11: Nyati emerald | L11: K pune | M11: Pristine O2 | O11: VJ Balewadi | P11: 182 | Q11: =16500+1500-150-1196+3000 -> 19654 | T11: CG | U11: 19092500 | W11: CG | X11: 19455500 | Y11: =15400000/X5*X7 -> 15830999 | AD11: We buy Loni Kalbhor plot for 32L. Balance 28L to give to Mama/Nana | AL11: =AL9*12.5% -> 416067.59 | AO11: Interest 5.25% for 5 years | AP11: =AP10*5.25%*5 -> 702187.5 | AR11: Interest 5.25% for 5 years | AS11: =AS10*5.25%*5 -> 727125 | AU11: Interest 5.25% for 5 years | AV11: =AV10*5.25%*5 -> 777000 | AX11: Interest 5.25% for 5 years | AY11: =AY10*5.25%*5 -> 804562.5 | BA11: Interest 5.25% for 5 years | BB11: =BB10*5.25%*5 -> 351750 | BD11: Interest 5.25% for 5 years | BE11: =BE10*5.25%*5 -> 364875 | BJ11: Interest 5.25% for 5 years | BK11: =BK10*5.25%*5 -> 786643.59 | BM11: Interest 5.25% for 5 years | BN11: =BN10*5.25%*5 -> 786643.59
C12: 0.2 | D12: 1706305 | E12: 85315 | F12: 17063 | G12: =D12+E12-F12 -> 1774557 | I12: 1258401 | K12: =101.64+11.07 -> 112.71 | L12: =92.74+10.96 -> 103.7 | M12: =92.04 -> 92.04 | O12: 104.47 | P12: =SUM(P3:P11) -> 1413962 | T12: Investment | U12: 4100000 | W12: Investment | X12: 4100000 | AD12: Nana gives 2L to Mummy as gift | AO12: Tax 20% | AP12: =AP11*20% -> 140437.5 | AR12: Tax 20% | AS12: =AS11*20% -> 145425 | AU12: Tax 20% | AV12: =AV11*20% -> 155400 | AX12: Tax 20% | AY12: =AY11*20% -> 160912.5 | BA12: Tax 20% | BB12: =BB11*20% -> 70350 | BD12: Tax 20% | BE12: =BE11*20% -> 72975 | BJ12: Tax 20% | BK12: =BK11*20% -> 157328.72 | BM12: Tax 20% | BN12: =BN11*20% -> 157328.72
C13: Total 30% with GST | D13: =SUM(D11:D12)+E11+E12 -> 2687430 | F13: =SUM(F11:F12) -> 25595 | G13: =SUM(G11:G12) -> 2661835 | I13: 447905 | K13: =K12*10.7639 -> 1213.1992 | L13: =L12*10.7639 -> 1116.2164 | M13: =M12*10.7639 -> 990.70936 | O13: =O12*10.7639 -> 1124.5046 | T13: NetSaleConsideration | U13: 20000000 | W13: NetSaleConsideration | X13: 20000000 | Z13: 0.3 | AA13: =AA10*Z13 -> 2533865 | AO13: Net Interest | AP13: =AP11-AP12 -> 561750 | AR13: Net Interest | AS13: =AS11-AS12 -> 581700 | AU13: Net Interest | AV13: =AV11-AV12 -> 621600 | AX13: Net Interest | AY13: =AY11-AY12 -> 643650 | BA13: Net Interest | BB13: =BB11-BB12 -> 281400 | BD13: Net Interest | BE13: =BE11-BE12 -> 291900 | BJ13: Net Interest | BK13: =BK11-BK12 -> 629314.88 | BM13: Net Interest | BN13: =BN11-BN12 -> 629314.88
C14: Paid before agreement | D14: 1150000 | G14: 1150000 | I14: 447905 | Q14: 1299 | T14: Exemption | U14: =U11*U12/U13 -> 3913962.5 | W14: Exemption | X14: =X11*X12/X13 -> 3988377.5 | Z14: -150000 | AA14: =AA13+Z14 -> 2383865 | AD14: Mama sells vrindavan flat for 80L | AO14: Total Value | AP14: =AP10+AP13 -> 3236750 | AR14: Total Value | AS14: =AS10+AS13 -> 3351700 | AU14: Total Value | AV14: =AV10+AV13 -> 3581600 | AX14: Total Value | AY14: =AY10+AY13 -> 3708650 | BA14: Total Value | BB14: =BB10+BB13 -> 1621400 | BD14: Total Value | BE14: =BE10+BE13 -> 1681900 | BJ14: Total Value | BK14: =BK10+BK13 -> 3626052.4 | BM14: Total Value | BN14: =BN10+BN13 -> 3626052.4
C15: Remaining after agreement | D15: =D13-D14 -> 1537430 | G15: =G13-G14 -> 1511835 | I15: 447905 | K15: =13711350+959800+30000 -> 14701150 | L15: =9000000+630000+3000 -> 9633000 | M15: =11000000+770000+30000 -> 11800000 | N15: T5 301 | O15: =15044600+1053200+30000 -> 16127800 | Q15: 799 | T15: RemainingFromSale | U15: =U13-U14 -> 16086038 | W15: RemainingFromSale | X15: =X13-X14 -> 16011622 | Z15: GST | AA15: =AA14*AB3 -> 119193.25 | AD15: I sell PI flat to Mama for 82L. Balance 28L to receive from Mama/Nana
C16: Demanded | D16: 1537429 | G16: 1537429 | O16: =15223200+1065700+30000 -> 16318900 | Q16: 329 | Z16: First Installment | AA16: =AA14+AA15 -> 2503058.3 | AD16: We buy Loni Kalbhor plot for 32L. Balance 28L to give to Mama/Nana | AO16: FD after tax | AP16: =AP7-AP8 -> 2136832.6 | AR16: FD after tax | AS16: =AS7-AS8 -> 2417646.9 | AU16: FD after tax | AV16: =AV7-AV8 -> 2357541.9 | AX16: FD after tax | AY16: =AY7-AY8 -> 2667360.9 | BA16: FD after tax | BB16: =BB7-BB8 -> 1067652.6 | BD16: FD after tax | BE16: =BE7-BE8 -> 1207959.4 | BJ16: FD after tax | BK16: =BK7-BK8 -> 2622145.3 | BM16: FD after tax | BN16: =BN7-BN8 -> 2622145.3
K17: =13169643+921900+30000 -> 14121543 | L17: =11100000+777000+30000 -> 11907000 | M17: =11179462+782600+30000 -> 11992062 | N17: T5 1304 | O17: =14687500+1028200+30000 -> 15745700 | Q17: 1527 | T17: CG | U17: 19850000 | Y17: =180+31+7 -> 218 | Z17: SD + R | AA17: =AA4+AA5 -> 541891.92 | AD17: Balances offset | AO17: Interest 6.9% for 5 years | AP17: =AP16*6.9%*5 -> 737207.25 | AR17: Interest 6.9% for 5 years | AS17: =AS16*6.9%*5 -> 834088.17 | AU17: Interest 6.9% for 5 years | AV17: =AV16*6.9%*5 -> 813351.96 | AX17: Interest 6.9% for 5 years | AY17: =AY16*6.9%*5 -> 920239.52 | BA17: Interest 6.9% for 5 years | BB17: =BB16*6.9%*5 -> 368340.15 | BD17: Interest 6.9% for 5 years | BE17: =BE16*6.9%*5 -> 416745.98 | BJ17: Simple Interest 6.9% for 5 years | BK17: =BK16*6.9%*5 -> 904640.13 | BM17: Compound Interest 6.9% for 5 years
A18: CG | B18: 19500000 | G18: 1146550 | Q18: 299 | T18: Investment | U18: 17500000 | W18: Agreement | X18: 3841500 | AO18: Total Value | AP18: =AP16+AP17 -> 2874039.8 | AR18: Total Value | AS18: =AS16+AS17 -> 3251735 | AU18: Total Value | AV18: =AV16+AV17 -> 3170893.9 | AX18: Total Value | AY18: =AY16+AY17 -> 3587600.5 | BA18: Total Value | BB18: =BB16+BB17 -> 1435992.7 | BD18: Total Value | BE18: =BE16+BE17 -> 1624705.4 | BJ18: Tax 0% | BK18: =BK17*0% -> 0 | BM18: Tax 0% | BN18: =BN17*0% -> 0
A19: Land | B19: Bonds | C19: Flat (proportion) | D19: Flat (agreement value) | L19: =124.76+16.02 -> 140.78 | M19: =102.47 -> 102.47 | O19: =99.55+8.36 -> 107.91 | Q19: 569 | T19: NetSaleConsideration | U19: 20000000 | W19: SDR | X19: 262490 | Y19: =31*4.5% -> 1.395 | Z19: Total | AA19: =AA16+AA17 -> 3044950.2 | BJ19: Net Interest | BK19: =BK17-BK18 -> 904640.13 | BM19: Net Interest | BN19: =BN17-BN18 -> 0
A20: 4102000 | B20: 5000000 | C20: 10900000 | D20: 11400000 | L20: =L19*10.7639 -> 1515.3418 | M20: =M19*10.7639 -> 1102.9768 | O20: =O19*10.7639 -> 1161.5324 | Q20: 199 | T20: Exemption | U20: =U17*U18/U19 -> 17368750 | W20: Total | X20: =X19+X18 -> 4103990 | Y20: =5.25*15% -> 0.7875 | AO20: Difference Bonds vs FD | AP20: =AP14-AP18 -> 362710.15 | AR20: Difference Bonds vs FD | AS20: =AS14-AS18 -> 99964.953 | AU20: Difference Bonds vs FD | AV20: =AV14-AV18 -> 410706.14 | AX20: Difference Bonds vs FD | AY20: =AY14-AY18 -> 121049.54 | BA20: Difference Bonds vs FD | BB20: =BB14-BB18 -> 185407.25 | BD20: Difference Bonds vs FD | BE20: =BE14-BE18 -> 57194.641 | BJ20: Total Value | BK20: =BK16+BK19 -> 3526785.4 | BM20: Total Value | BN20: 3660540
A21: 4102000 | B21: 3250000 | C21: 12650000 | D21: 13000000 | G21: 746900 | H21: Total Cost to me till now | I21: =SUM(I3:I20) -> 5932760 | Q21: =SUM(Q14:Q20) -> 5021 | R21: =SUM(R2:R20) -> 6750 | S21: =SUM(S2:S20) -> 0 | T21: RemainingFromSale | U21: =U19-U20 -> 2631250 | Y21: =9620000+5000000+4000000 -> 18620000
A22: 4102000 | B22: 0 | C22: 15400000 | D22: 15840000 | G22: =426078+200 -> 426278 | H22: Paid to builder till now | I22: =I21-I3-I4 -> 5374860 | L22: =16537000+1157600+30000 -> 17724600 | M22: =13116964+787100+30000 -> 13934064 | O22: =15223200+1065700+30000 -> 16318900 | S22: =S21+R21 -> 6750 | Y22: =U26+X26 -> 16973735 | BJ22: Difference Bonds vs FD | BK22: =BK14-BK20 -> 99266.93 | BM22: Difference Bonds vs FD | BN22: =BN14-BN20 -> -34487.625
A23: Bonds - REC or PFC. NHAI is discontinued | G23: 240000 | H23: Total to be paid to builder (A+B) | I23: =8531524+426576 -> 8958100 | T23: CG | U23: 19850000 | W23: CG | X23: 19850000 | AK23: ✅ Comparison With and Without Indexation
G24: =G21-G22-G23 -> 80622 | H24: Pending to be paid to builder | I24: =I23-I22 -> 3583240 | L24: =15779000+1104600+30000 -> 16913600 | M24: =13822321+967600+30000 -> 14819921 | O24: 887278 | P24: 3839186 | Q24: =853152+42658 -> 895810 | R24: 8532 | T24: Investment | U24: 4102000 | W24: Investment | X24: 13000000
O25: 1774557 | P25: 191959 | Q25: =1706305+85315 -> 1791620 | R25: 17063 | T25: NetSaleConsideration | U25: 20000000 | W25: NetSaleConsideration | X25: 20000000 | AK25: Basis | AL25: Capital Gain | AM25: Exemption (Sec 54) | AN25: Taxable Gain | AO25: Tax Rate | AP25: Tax (with cess)
L26: =16008000+1120600+30000 -> 17158600 | O26: 1330918 | P26: =SUM(P24:P25) -> 4031145 | Q26: =1279729+63986 -> 1343715 | R26: 12797 | T26: Exemption | U26: =U23*U24/U25 -> 4071235 | W26: Exemption | X26: =X23*X24/X25 -> 12902500 | AK26: With Indexation | AL26: 19092500 | AM26: 17102000 | AN26: 1990500 | AO26: 0.2 | AP26: ₹4,14,024 ✅
N27: =P26-O27 -> 38392 | O27: =SUM(O24:O26) -> 3992753 | Q27: =SUM(Q24:Q26) -> 4031145 | R27: =SUM(R24:R26) -> 38392 | T27: RemainingFromSale | U27: =U25-U26 -> 15928765 | W27: RemainingFromSale | X27: =X25-X26 -> 7097500 | AK27: Without Indexation | AL27: 19750000 | AM27: 17102000 | AN27: 2648000 | AO27: 0.125 | AP27: ₹3,71,400 ✅
BI29: salary
AK30: Invest 20 Lakhs in 54EC bonds | BI30: 215696
AK31: Option | AL31: Maturity Amount (5 Years) | BI31: 218696
AK32: 54EC Bonds (5.25%, 20% tax) | AL32: ₹24,20,000 ✅ | BI32: 213296
AK33: FD at 6.90% after paying LTCG tax | AL33: 2209132 | BI33: 215276
AK34: Net Advantage of 54EC Bonds | AL34: 210868 | BI34: 257852
BI35: 289324
BI36: 19512
BH37: total salary | BI37: =SUM(BI30:BI36) -> 1429652
AK38: Flat ₹1.31 Cr + Land ₹41.02L = ₹1,72,02,000 Reinvested
BI39: 26AS:
AK40: Exemption=₹1,90,92,500×(1,72,02,0002,00,00,000)=₹1,90,92,500×0.8601≈₹1,64,31,543\text{Exemption} = ₹1,90,92,500 × \left( \frac{1,72,02,000}{2,00,00,000} \right) = ₹1,90,92,500 × 0.8601 ≈ ₹1,64,31,543Exemption=₹1,90,92,500×(2,00,00,0001,72,02,000​)=₹1,90,92,500×0.8601≈₹1,64,31,543 | BI40: salary before tax | BJ40: tax | BK40: net tax
BI41: 1962230 | BJ41: 426000 | BK41: =1962230-426000 -> 1536230
...

Sheet Sheet2
A1: Building | D1: Building | F1: Building
A2: Al Manal Pearl | D2: Binghatti point | F2: The White Palace
A3: Al Manal Residence 1 | D3: Nova tower
A4: Al Manal Residence 2 | D4: ASB Tower | I4: silicon avenue
A5: Arabian Gate | D5: Axis 1 | I5: la vista 3
A6: Axis 5 | D6: S Residence (bad management)
A7: Axis 6 | D7: Axis 7
A8: Axis 8 | D8: Axis 4
A9: Binghatti Apartments | D9: Mirage 1
A10: Imperial Tower | D10: Le Presidium 1
A11: La Vista 1, 2, 3 | D11: Altia
A12: la vista 6
A13: Mirage 3 | D13: Le Presidium 2
A14: Oasis High Park | D14: Silicon arch | L14: 139748
A15: Palace Tower | D15: Al Thuraya | L15: 62000
A16: Ruby Residence | D16: Coral residence | L16: 43451
A17: Sapphire Residences | L17: =L14+L15-L16 -> 158297
A18: Silicon Avenue | D18: Palacio tower | L18: 448000
A19: Silicon Gate 1 | L19: =L17+L18 -> 606297
A20: SP Oasis | D20: Park Terrace
A21: Spring Oasis | D21: Lynx
A22: Silicon Star 2

Sheet Sheet1
A1: DA | B1: HRA | C1: Month | D1: Days | E1: PAY | F1: DA | G1: HRA | H1: CLA | I1: TA | J1: OTHER | K1: TOTAL
A2: 53 | B2: 30 | C2: Sep-2024 (from 4-Sep) | D2: 27 | E2: 164430 | F2: =E2*A2/100 -> 87147.9 | G2: =E2*B2/100 -> 49329 | H2: 216 | I2: 4860 | J2: 4050 | K2: =SUM(E2:J2) -> 310032.9
A3: 53 | B3: 30 | C3: 45566 | D3: 30 | E3: 182700 | F3: =E3*A3/100 -> 96831 | G3: =E3*B3/100 -> 54810 | H3: 240 | I3: 5400 | J3: 4500 | K3: =SUM(E3:J3) -> 344481
A4: 53 | B4: 30 | C4: 45597 | D4: 30 | E4: 182700 | F4: =E4*A4/100 -> 96831 | G4: =E4*B4/100 -> 54810 | H4: 240 | I4: 5400 | J4: 4500 | K4: =SUM(E4:J4) -> 344481
A5: 53 | B5: 30 | C5: 45627 | D5: 30 | E5: 182700 | F5: =E5*A5/100 -> 96831 | G5: =E5*B5/100 -> 54810 | H5: 240 | I5: 5400 | J5: 4500 | K5: =SUM(E5:J5) -> 344481
A6: 55 | B6: 30 | C6: 45658 | D6: 30 | E6: 188200 | F6: =E6*A6/100 -> 103510 | G6: =E6*B6/100 -> 56460 | H6: 240 | I6: 5400 | J6: 4500 | K6: =SUM(E6:J6) -> 358310
A7: 55 | B7: 30 | C7: 45689 | D7: 30 | E7: 188200 | F7: =E7*A7/100 -> 103510 | G7: =E7*B7/100 -> 56460 | H7: 240 | I7: 5400 | J7: 4500 | K7: =SUM(E7:J7) -> 358310
A8: 55 | B8: 30 | C8: 45717 | D8: 30 | E8: 188200 | F8: =E8*A8/100 -> 103510 | G8: =E8*B8/100 -> 56460 | H8: 240 | I8: 5400 | J8: 4500 | K8: =SUM(E8:J8) -> 358310
A9: 55 | B9: 30 | C9: 45748 | D9: 30 | E9: 188200 | F9: =E9*A9/100 -> 103510 | G9: =E9*B9/100 -> 56460 | H9: 240 | I9: 5400 | J9: 4500 | K9: =SUM(E9:J9) -> 358310
A10: 55 | B10: 30 | C10: 45778 | D10: 30 | E10: 188200 | F10: =E10*A10/100 -> 103510 | G10: =E10*B10/100 -> 56460 | H10: 240 | I10: 5400 | J10: 4500 | K10: =SUM(E10:J10) -> 358310
A11: 55 | B11: 30 | C11: 45809 | D11: 30 | E11: 188200 | F11: =E11*A11/100 -> 103510 | G11: =E11*B11/100 -> 56460 | H11: 240 | I11: 5400 | J11: 4500 | K11: =SUM(E11:J11) -> 358310
A12: 55 | B12: 30 | C12: Jul-2025 (1–16 Jul) | D12: 16 | E12: =E11*D12/D11 -> 100373.33 | F12: =E12*A12/100 -> 55205.333 | G12: =E12*B12/100 -> 30112 | H12: 128 | I12: 2880 | J12: 2400 | K12: =SUM(E12:J12) -> 191098.67
E13: =SUM(E2:E12) -> 1942103.3 | F13: =SUM(F2:F12) -> 1053906.2 | G13: =SUM(G2:G12) -> 582631 | H13: =SUM(H2:H12) -> 2504 | I13: =SUM(I2:I12) -> 56340 | J13: =SUM(J2:J12) -> 46950 | K13: =SUM(K2:K12) -> 3684434.6

Sheet Equity
A1: FOR KOHINOOR FLAT, MY PURCHASE COST IS RS. 42,65,762. IN FY 2024-25, RS. 23,77,210 WORTH DEBT FUNDS REDEMPTION WAS CLAIMED UNDER SECTION 54F EXEMPTION FOR LTCG ON THE DEBT FUNDS.
A2: REMAINING RS. 18,88,552 CAN STILL BE CLAIMED UNDER SECTION 54F AND ALL LTCG FROM THIS AMOUNT WILL BE EXEMPTED.
A3: NIFTYBEES SELL VALUE IS 1275077. HDFC NIFTY 50 INDEX FUND SELL VALUE IS 602749. TOTAL RS. 1877826 CAN BE CLAIMED UNDER SECTION 54F.
A4: MENTION DAY WISE ENTRIES WHILE ADDING LTCG ENTRIES AND ALSO SECTION 54F ENTRIES.
A6: LTCG:
A7: DATE | B7: BUY VALUE | C7: SELL VALUE | D7: P&L
A8: 45887 | B8: 436900 | C8: 562800 | D8: 125900 | E8: NIFTYBEES
A9: 45888 | B9: 553115.4 | C9: 712276.92 | D9: 159161.52 | E9: NIFTYBEES
A10: 45890 | B10: 492390.25 | C10: 602749.52 | D10: 110359.27 | E10: HDFC NIFTY 50 INDEX FUND
C11: =SUM(C8:C10) -> 1877826.4 | D11: =SUM(D8:D10) -> 395420.79
A13: NIFTYBEES TOTAL | N13: NIFTYBEES SELL ON 18-08-2025
A15: Symbol | B15: ISIN | C15: Entry Date | D15: Exit Date | E15: Quantity | F15: Buy Value | G15: Sell Value | H15: Profit | I15: Period of Holding | J15: Fair Market Value | K15: Taxable Profit | L15: Turnover | N15: Symbol | O15: ISIN | P15: Entry Date | Q15: Exit Date | R15: Quantity | S15: Buy Value | T15: Sell Value | U15: Profit | V15: Period of Holding | W15: Fair Market Value | X15: Taxable Profit | Y15: Turnover
A16: NIFTYBEES | B16: INF204KB14I2 | C16: 2023-11-24 | D16: 2025-08-18 | E16: 8 | F16: 1747.6 | G16: 2251.2 | H16: 503.6 | I16: 633 | J16: 0 | K16: 503.6 | L16: 0 | N16: NIFTYBEES | O16: INF204KB14I2 | P16: 2023-11-24 | Q16: 2025-08-18 | R16: 8 | S16: 1747.6 | T16: 2251.2 | U16: 503.6 | V16: 633 | W16: 0 | X16: 503.6 | Y16: 0
